{
	"deprecated": false,
	"cpeName": "cpe:2.3:a:debian:pyftpd:0.8.4:*:*:*:*:*:*:*",
	"cpeNameId": "8BAD189E-4A97-467D-8562-BDAF5F987AF0",
	"created": "2024-02-17T15:22:29.847",
	"lastModified": "2024-02-17T15:22:29.847",
	"titles": [
		{
			"title": "Debian Pyftpd 0.8.4",
			"lang": "en"
		}
	],
	"refs": [
		{
			"ref": "https://exchange.xforce.ibmcloud.com/vulnerabilities/59431",
			"type": "Advisory"
		},
		{
			"ref": "https://bugs.debian.org/cgi-bin/bugreport.cgi?bug=585776",
			"type": "Advisory"
		}
	]
}
